<?xml version="1.0"?>
<robot xmlns:xacro="http://www.ros.org/wiki/xacro" >
<xacro:include filename="inertial_macros.xacro" />

    <material name="white">
        <color rgba="1 1 1 1" />
    </material>

    <material name="orange">
        <color rgba="1 0.3 0.1 1"/>
    </material>

    <material name="blue">
        <color rgba="0.2 0.2 1 1"/>
    </material>

    <material name="black">
        <color rgba="0 0 0 1"/>
    </material>

    <material name="red">
        <color rgba="1 0 0 1"/>
    </material>

    <link name="base_link">

    </link>

    <joint name="base_footprint_joint" type="fixed">
        <parent link="base_link"/>
        <child link="base_footprint"/>
        <origin xyz="0 0 0" rpy="0 0 0"/>
    </joint>

    <link name="base_footprint">

    </link>

    <joint name="body_joint" type="fixed">
        <parent link="base_footprint"/>
        <child link="body"/>
        <origin xyz="0 0 0" rpy="0 0 0"/>
    </joint>

    <!-- ฐานหุ่นยนต์ -->
    <link name="body">
        <visual>
            <geometry>
                <mesh filename="file:///home/preeyanan/robotic2/src/articubot_nuy/meshes/body.dae" scale="1 1 1"/>
            </geometry>
        </visual>
        <collision>
            <geometry>
                <mesh filename="file:///home/preeyanan/robotic2/src/articubot_nuy/meshes/body.dae" scale="1 1 1"/>
            </geometry>
        </collision>
        <xacro:inertial_box mass="5" x="0.46" y="0.55" z="0.40">
            <origin xyz="0 0 0" rpy="0 0 0"/>
        </xacro:inertial_box>
    </link>
    <gazebo reference="body">
        <material>Gazebo/White</material>
    </gazebo>

    <!-- === ล้อหน้า ซ้าย === -->
    <joint name="front_right_wheel_joint" type="continuous">
        <parent link="body"/>
        <child link="front_right_wheel"/>
        <origin xyz="0.193 -0.1481 0.0198" rpy="0 0 0"/>
        <axis xyz="1 0 0"/>
    </joint>

    <link name="front_left_wheel">
        <visual>
            <geometry>
                <mesh filename="file:///home/preeyanan/robotic2/src/articubot_nuy/meshes/frontwheel.dae" scale="1 1 1"/>
            </geometry>
        </visual>
        <collision>
            <geometry>
                <mesh filename="file:///home/preeyanan/robotic2/src/articubot_nuy/meshes/frontwheel.dae" scale="1 1 1"/>
            </geometry>
        </collision>
        <xacro:inertial_cylinder mass="0.6" length="0.1" radius="0.09">
            <origin xyz="0 0 0" rpy="0 0 0"/>
        </xacro:inertial_cylinder>
    </link>
    <gazebo reference="front_left_wheel">
        <material>Gazebo/Black</material>
    </gazebo>

    <!-- === ล้อหน้า ขวา === -->
    <joint name="front_left_wheel_joint" type="continuous">
        <parent link="body"/>
        <child link="front_left_wheel"/>
        <origin xyz="-0.2007 -0.1481 0.0198" rpy="0 0 0"/>
        <axis xyz="1 0 0"/>
    </joint>

    <link name="front_right_wheel">
        <visual>
            <geometry>
                <mesh filename="file:///home/preeyanan/robotic2/src/articubot_nuy/meshes/frontwheel.dae" scale="1 1 1"/>
            </geometry>
        </visual>
        <collision>
            <geometry>
                <mesh filename="file:///home/preeyanan/robotic2/src/articubot_nuy/meshes/frontwheel.dae" scale="1 1 1"/>
            </geometry>
        </collision>
        <xacro:inertial_cylinder mass="0.6" length="0.1" radius="0.09">
            <origin xyz="0 0 0" rpy="0 0 0"/>
        </xacro:inertial_cylinder>
    </link>
    <gazebo reference="front_right_wheel">
        <material>Gazebo/Black</material>
    </gazebo>

    <!-- === ล้อหลัง ซ้าย === -->
    <joint name="back_left_wheel_joint" type="continuous">
        <parent link="body"/>
        <child link="back_left_wheel"/>
        <origin xyz="0.1925 0.1518 0.05" rpy="0 0 0"/>
        <axis xyz="1 0 0"/>
    </joint>

    <link name="back_left_wheel">
        <visual>
            <geometry>
                <mesh filename="file:///home/preeyanan/robotic2/src/articubot_nuy/meshes/backwheel.dae" scale="1 1 1"/>
            </geometry>
        </visual>
        <collision>
            <geometry>
                <mesh filename="file:///home/preeyanan/robotic2/src/articubot_nuy/meshes/backwheel.dae" scale="1 1 1"/>
            </geometry>
        </collision>
        <xacro:inertial_cylinder mass="1" length="0.1" radius="0.12">
            <origin xyz="0 0 0" rpy="0 0 0"/>
        </xacro:inertial_cylinder>
    </link>
    <gazebo reference="back_left_wheel">
        <material>Gazebo/Black</material>
    </gazebo>

    <!-- === ล้อหลัง ขวา === -->
    <joint name="back_right_wheel_joint" type="continuous">
        <parent link="body"/>
        <child link="back_right_wheel"/>
        <origin xyz="-0.2017 0.1518 0.05" rpy="0 0 0"/>
        <axis xyz="1 0 0"/>
    </joint>

    <link name="back_right_wheel">
        <visual>
            <geometry>
                <mesh filename="file:///home/preeyanan/robotic2/src/articubot_nuy/meshes/backwheel.dae" scale="1 1 1"/>
            </geometry>
        </visual>
        <collision>
            <geometry>
                <mesh filename="file:///home/preeyanan/robotic2/src/articubot_nuy/meshes/backwheel.dae" scale="1 1 1"/>
            </geometry>
        </collision>
        <xacro:inertial_cylinder mass="1" length="0.1" radius="0.12">
            <origin xyz="0 0 0" rpy="0 0 0"/>
        </xacro:inertial_cylinder>
    </link>
    <gazebo reference="back_right_wheel">
        <material>Gazebo/Black</material>
    </gazebo>

    <!-- === LR L === -->
    <joint name="LR_L_joint" type="prismatic">
        <parent link="body"/>
        <child link="LR_L"/>
        <origin xyz="0.1425 -0.296 0.095" rpy="0 0 0"/>
        <axis xyz="1 0 0"/>
        <limit lower="-0.125" upper="0" effort="1" velocity="-1"/>
    </joint>

    <link name="LR_L">
        <visual>
            <geometry>
                <mesh filename="file:///home/preeyanan/robotic2/src/articubot_nuy/meshes/LR.dae" scale="1 1 1"/>
            </geometry>
        </visual>
        <collision>
            <geometry>
                <mesh filename="file:///home/preeyanan/robotic2/src/articubot_nuy/meshes/LR.dae" scale="1 1 1"/>
            </geometry>
        </collision>
        <xacro:inertial_box mass="0.3" x="0.03" y="0.03" z="0.2">
            <origin xyz="0 0 0" rpy="0 0 0"/>
        </xacro:inertial_box>
    </link>
    <gazebo reference="LR_L">
        <material>Gazebo/White</material>
    </gazebo>

    <!-- === LR R === -->
    <joint name="LR_R_joint" type="prismatic">
        <parent link="body"/>
        <child link="LR_R"/>
        <origin xyz="-0.139 -0.296 0.095" rpy="0 0 0"/>
        <axis xyz="1 0 0"/>
        <limit lower="0" upper="0.125" effort="1" velocity="1"/>
    </joint>
    <link name="LR_R">
        <visual>
            <geometry>
                <mesh filename="file:///home/preeyanan/robotic2/src/articubot_nuy/meshes/LR.dae" scale="1 1 1"/>
            </geometry>
        </visual>
        <collision>
            <geometry>
                <mesh filename="file:///home/preeyanan/robotic2/src/articubot_nuy/meshes/LR.dae" scale="1 1 1"/>
            </geometry>
        </collision>
        <xacro:inertial_box mass="0.3" x="0.03" y="0.03" z="0.2">
            <origin xyz="0 0 0" rpy="0 0 0"/>
        </xacro:inertial_box>
    </link>
    <gazebo reference="LR_R">
        <material>Gazebo/White</material>
    </gazebo>

    <!-- === UD L === -->
    <joint name="UD_L_joint" type="prismatic">
        <parent link="LR_L"/>
        <child link="UD_L"/>
        <origin xyz="0 -0.03 0" rpy="0 0 0"/>
        <axis xyz="0 0 1"/>
        <limit lower="-0.085" upper="0.085" effort="1" velocity="-1"/>
    </joint>

    <link name="UD_L">
        <visual>
            <geometry>
                <mesh filename="file:///home/preeyanan/robotic2/src/articubot_nuy/meshes/UDL.dae" scale="1 1 1"/>
            </geometry>
        </visual>
        <collision>
            <geometry>
                <mesh filename="file:///home/preeyanan/robotic2/src/articubot_nuy/meshes/UDL.dae" scale="1 1 1"/>
            </geometry>
        </collision>
        <xacro:inertial_box mass="0.2" x="0.03" y="0.03" z="0.15">
            <origin xyz="0 0 0" rpy="0 0 0"/>
        </xacro:inertial_box>
    </link>
    <gazebo reference="UD_L">
        <material>Gazebo/White</material>
    </gazebo>

    <!-- === UD R === -->
    <joint name="UD_R_joint" type="prismatic">
        <parent link="LR_R"/>
        <child link="UD_R"/>
        <origin xyz="0 -0.03 0" rpy="0 0 0"/>
        <axis xyz="0 0 1"/>
        <limit lower="-0.085" upper="0.085" effort="1" velocity="-1"/>
    </joint>

    <link name="UD_R">
        <visual>
            <geometry>
                <mesh filename="file:///home/preeyanan/robotic2/src/articubot_nuy/meshes/UDR.dae" scale="1 1 1"/>
            </geometry>
        </visual>
        <collision>
            <geometry>
                <mesh filename="file:///home/preeyanan/robotic2/src/articubot_nuy/meshes/UDR.dae" scale="1 1 1"/>
            </geometry>
        </collision>
        <xacro:inertial_box mass="0.2" x="0.03" y="0.03" z="0.15">
            <origin xyz="0 0 0" rpy="0 0 0"/>
        </xacro:inertial_box>
    </link>
    <gazebo reference="UD_R">
        <material>Gazebo/White</material>
   </gazebo>

</robot>
